Workbook
Name Slicer_attendance_group: #N/A
Name Slicer_grade: #N/A
Name Slicer_score_group: #N/A
Name Slicer_study_hours_group: #N/A

Sheet grade distribution
A1: Row Labels | B1: Count of student_id
A2: A | B2: 10
A3: B | B3: 7
A4: C | B4: 7
A5: D | B5: 1
A6: Grand Total | B6: 25

Sheet average score by grade
A1: Row Labels | B1: Average of total_score
A2: A | B2: 97.87
A3: B | B3: 77.271429
A4: C | B4: 63.571429
A5: D | B5: 52.1
A6: Grand Total | B6: 80.668

Sheet average attendance by grade
A1: Row Labels | B1: Average of attendance_percentage
A2: A | B2: 82.21
A3: B | B3: 86.342857
A4: C | B4: 88.857143
A5: D | B5: 90.7
A6: Grand Total | B6: 85.568

Sheet average study hours by grade
A1: Row Labels | B1: Average of weekly_self_study_hours
A2: A | B2: 19.62
A3: B | B3: 13.3
A4: C | B4: 7.7571429
A5: D | B5: 2.9
A6: Grand Total | B6: 13.86

Sheet   score by study hours group
A1: Row Labels | B1: Average of total_score
A2: High (10h+) | B2: 86.773684
A3: Low (<5h) | B3: 56.5
A4: Medium (5-10h) | B4: 63.75
A5: Grand Total | B5: 80.668

Sheet score by attendance group
A1: Row Labels | B1: Average of total_score
A2: 75-89% | B2: 84.65
A3: 90-100% | B3: 73.37
A4: Below 75% | B4: 87.3
A5: Grand Total | B5: 80.668

Sheet kpi
A1: Count of student_id | C1: Average of total_score | E1: Average of attendance_percentage | G1: Average of weekly_self_study_hours
A2: 25 | C2: 80.668 | E2: 85.568 | G2: 13.86

Sheet calculation
A1: =GETPIVOTDATA("student_id",kpi!$A$1) -> 25 | C1: =GETPIVOTDATA("total_score",kpi!$C$1) -> 80.668 | E1: =GETPIVOTDATA("attendance_percentage",kpi!$E$1) -> 85.568 | G1: =GETPIVOTDATA("weekly_self_study_hours",kpi!$G$1) -> 13.86

Sheet student_performance
A1: student_id | B1: weekly_self_study_hours | C1: attendance_percentage | D1: class_participation | E1: total_score | F1: grade | G1: attendance_group | H1: study_hours_group | I1: score_group
A2: 1 | B2: 18.5 | C2: 95.6 | D2: 3.8 | E2: 97.9 | F2: A | G2: =IF(C2>=90,"90-100%",IF(C2>=75,"75-89%","Below 75%")) -> 90-100% | H2: =IF(B2<5,"Low (<5h)",IF(B2<10,"Medium (5-10h)","High (10h+)")) -> High (10h+) | I2: =IF(E2>=85,"Excellent",IF(E2>=70,"Good",IF(E2>=50,"Average","Needs Improvement"))) -> Excellent
A3: 2 | B3: 14 | C3: 80 | D3: 2.5 | E3: 83.9 | F3: B | G3: =IF(C3>=90,"90-100%",IF(C3>=75,"75-89%","Below 75%")) -> 75-89% | H3: =IF(B3<5,"Low (<5h)",IF(B3<10,"Medium (5-10h)","High (10h+)")) -> High (10h+) | I3: =IF(E3>=85,"Excellent",IF(E3>=70,"Good",IF(E3>=50,"Average","Needs Improvement"))) -> Good
A4: 3 | B4: 19.5 | C4: 86.3 | D4: 5.3 | E4: 100 | F4: A | G4: =IF(C4>=90,"90-100%",IF(C4>=75,"75-89%","Below 75%")) -> 75-89% | H4: =IF(B4<5,"Low (<5h)",IF(B4<10,"Medium (5-10h)","High (10h+)")) -> High (10h+) | I4: =IF(E4>=85,"Excellent",IF(E4>=70,"Good",IF(E4>=50,"Average","Needs Improvement"))) -> Excellent
A5: 4 | B5: 25.7 | C5: 70.2 | D5: 7 | E5: 100 | F5: A | G5: =IF(C5>=90,"90-100%",IF(C5>=75,"75-89%","Below 75%")) -> Below 75% | H5: =IF(B5<5,"Low (<5h)",IF(B5<10,"Medium (5-10h)","High (10h+)")) -> High (10h+) | I5: =IF(E5>=85,"Excellent",IF(E5>=70,"Good",IF(E5>=50,"Average","Needs Improvement"))) -> Excellent
A6: 5 | B6: 13.4 | C6: 81.9 | D6: 6.9 | E6: 92 | F6: A | G6: =IF(C6>=90,"90-100%",IF(C6>=75,"75-89%","Below 75%")) -> 75-89% | H6: =IF(B6<5,"Low (<5h)",IF(B6<10,"Medium (5-10h)","High (10h+)")) -> High (10h+) | I6: =IF(E6>=85,"Excellent",IF(E6>=70,"Good",IF(E6>=50,"Average","Needs Improvement"))) -> Excellent
A7: 6 | B7: 13.4 | C7: 65.1 | D7: 5 | E7: 97.5 | F7: A | G7: =IF(C7>=90,"90-100%",IF(C7>=75,"75-89%","Below 75%")) -> Below 75% | H7: =IF(B7<5,"Low (<5h)",IF(B7<10,"Medium (5-10h)","High (10h+)")) -> High (10h+) | I7: =IF(E7>=85,"Excellent",IF(E7>=70,"Good",IF(E7>=50,"Average","Needs Improvement"))) -> Excellent
A8: 7 | B8: 26.1 | C8: 81.8 | D8: 5.9 | E8: 100 | F8: A | G8: =IF(C8>=90,"90-100%",IF(C8>=75,"75-89%","Below 75%")) -> 75-89% | H8: =IF(B8<5,"Low (<5h)",IF(B8<10,"Medium (5-10h)","High (10h+)")) -> High (10h+) | I8: =IF(E8>=85,"Excellent",IF(E8>=70,"Good",IF(E8>=50,"Average","Needs Improvement"))) -> Excellent
A9: 8 | B9: 20.4 | C9: 100 | D9: 4 | E9: 96.1 | F9: A | G9: =IF(C9>=90,"90-100%",IF(C9>=75,"75-89%","Below 75%")) -> 90-100% | H9: =IF(B9<5,"Low (<5h)",IF(B9<10,"Medium (5-10h)","High (10h+)")) -> High (10h+) | I9: =IF(E9>=85,"Excellent",IF(E9>=70,"Good",IF(E9>=50,"Average","Needs Improvement"))) -> Excellent
A10: 9 | B10: 11.7 | C10: 100 | D10: 8.2 | E10: 69.8 | F10: C | G10: =IF(C10>=90,"90-100%",IF(C10>=75,"75-89%","Below 75%")) -> 90-100% | H10: =IF(B10<5,"Low (<5h)",IF(B10<10,"Medium (5-10h)","High (10h+)")) -> High (10h+) | I10: =IF(E10>=85,"Excellent",IF(E10>=70,"Good",IF(E10>=50,"Average","Needs Improvement"))) -> Average
A11: 10 | B11: 18.8 | C11: 67.6 | D11: 6 | E11: 80.3 | F11: B | G11: =IF(C11>=90,"90-100%",IF(C11>=75,"75-89%","Below 75%")) -> Below 75% | H11: =IF(B11<5,"Low (<5h)",IF(B11<10,"Medium (5-10h)","High (10h+)")) -> High (10h+) | I11: =IF(E11>=85,"Excellent",IF(E11>=70,"Good",IF(E11>=50,"Average","Needs Improvement"))) -> Good
A12: 11 | B12: 11.8 | C12: 82.3 | D12: 4.6 | E12: 66.4 | F12: C | G12: =IF(C12>=90,"90-100%",IF(C12>=75,"75-89%","Below 75%")) -> 75-89% | H12: =IF(B12<5,"Low (<5h)",IF(B12<10,"Medium (5-10h)","High (10h+)")) -> High (10h+) | I12: =IF(E12>=85,"Excellent",IF(E12>=70,"Good",IF(E12>=50,"Average","Needs Improvement"))) -> Average
A13: 12 | B13: 11.7 | C13: 75.9 | D13: 7.6 | E13: 72.5 | F13: B | G13: =IF(C13>=90,"90-100%",IF(C13>=75,"75-89%","Below 75%")) -> 75-89% | H13: =IF(B13<5,"Low (<5h)",IF(B13<10,"Medium (5-10h)","High (10h+)")) -> High (10h+) | I13: =IF(E13>=85,"Excellent",IF(E13>=70,"Good",IF(E13>=50,"Average","Needs Improvement"))) -> Good
... A26: 25 | B26: 11.2 | C26: 96.1 | D26: 4.9 | E26: 68.3 | F26: C | G26: =IF(C26>=90,"90-100%",IF(C26>=75,"75-89%","Below 75%")) -> 90-100% | H26: =IF(B26<5,"Low (<5h)",IF(B26<10,"Medium (5-10h)","High (10h+)")) -> High (10h+) | I26: =IF(E26>=85,"Excellent",IF(E26>=70,"Good",IF(E26>=50,"Average","Needs Improvement"))) -> Average
A18621: 18620 | B18621: 15.7 | C18621: 77.9 | D18621: 2.6 | E18621: 78.1 | F18621: B
A18622: 18621 | B18622: 25.6 | C18622: 71.9 | D18622: 8.5 | E18622: 100 | F18622: A
A18623: 18622 | B18623: 14.7 | C18623: 79.6 | D18623: 7.9 | E18623: 81.2 | F18623: B
A18624: 18623 | B18624: 0 | C18624: 80.8 | D18624: 6 | E18624: 44.4 | F18624: D
A18625: 18624 | B18625: 17.7 | C18625: 90.5 | D18625: 4 | E18625: 94 | F18625: A
A18626: 18625 | B18626: 13.6 | C18626: 94 | D18626: 6.6 | E18626: 86.4 | F18626: A
A18627: 18626 | B18627: 2.2 | C18627: 97 | D18627: 2.4 | E18627: 54.8 | F18627: D
A18628: 18627 | B18628: 3.2 | C18628: 84.3 | D18628: 6 | E18628: 61.2 | F18628: C
A18629: 18628 | B18629: 21.8 | C18629: 82.6 | D18629: 6.4 | E18629: 100 | F18629: A
A18630: 18629 | B18630: 9.9 | C18630: 89.3 | D18630: 5.7 | E18630: 64.2 | F18630: C
A18631: 18630 | B18631: 8.6 | C18631: 90.2 | D18631: 6.5 | E18631: 65.4 | F18631: C
A18632: 18631 | B18632: 14.8 | C18632: 96.6 | D18632: 4.3 | E18632: 94.6 | F18632: A
... A235407: 235406 | B235407: 17.1 | C235407: 81.1 | D235407: 9.7 | E235407: 77.5 | F235407: B
A381119: 381118
A381120: 381119
A381121: 381120
A381122: 381121
A381123: 381122
A381124: 381123
A381125: 381124
A381126: 381125
A381127: 381126
A381128: 381127
A381129: 381128
A381130: 381129
... A382002: 382001
...

Sheet Dashboard
G5: =student_performance!A2 -> 1
